<?xml version="1.0" ?>
<sdf version='1.6'>
  <model name='mobile_robot'>
    <link name='base_footprint'>
      <inertial>
        <pose>-0.010843 0 0.151251 0 -0 0</pose>
        <mass>79.4</mass>
        <inertia>
          <ixx>0.983281</ixx>
          <ixy>-0.221872</ixy>
          <ixz>-0.00481783</ixz>
          <iyy>2.25112</iyy>
          <iyz>0</iyz>
          <izz>2.69939</izz>
        </inertia>
      </inertial>
      <collision name='base_footprint_fixed_joint_lump__mirX/base_link_collision'>
        <pose>0.037646 0 0 0 -0 0</pose>
        <geometry>
          <mesh>
            <scale>1 1 1</scale>
            <uri>model://mobile_robot/meshes/collision/mir_100_base.stl</uri>
          </mesh>
        </geometry>
        <surface>
          <contact>
            <ode/>
          </contact>
          <friction>
            <ode/>
          </friction>
        </surface>
      </collision>
      <collision name='base_footprint_fixed_joint_lump__mirX/back_laser_link_collision_1'>
        <pose>-0.354354 -0.2358 0.1914 3.14159 -0 -2.35619</pose>
        <geometry>
          <mesh>
            <scale>1 1 1</scale>
            <uri>model://mobile_robot/meshes/visual/sick_lms-100.stl</uri>
          </mesh>
        </geometry>
        <surface>
          <contact>
            <ode/>
          </contact>
          <friction>
            <ode/>
          </friction>
        </surface>
      </collision>
      <collision name='base_footprint_fixed_joint_lump__mirX/front_laser_link_collision_2'>
        <pose>0.429646 0.2358 0.1914 3.14159 -0 0.785398</pose>
        <geometry>
          <mesh>
            <scale>1 1 1</scale>
            <uri>model://mobile_robot/meshes/visual/sick_lms-100.stl</uri>
          </mesh>
        </geometry>
        <surface>
          <contact>
            <ode/>
          </contact>
          <friction>
            <ode/>
          </friction>
        </surface>
      </collision>
      <visual name='base_footprint_fixed_joint_lump__mirX/base_link_visual'>
        <pose>0.037646 0 0 0 -0 0</pose>
        <geometry>
          <mesh>
            <scale>1 1 1</scale>
            <uri>model://mobile_robot/meshes/visual/mir_100_base.stl</uri>
          </mesh>
        </geometry>
        <material>
          <script>
            <name>Gazebo/White</name>
            <uri>model://media/materials/scripts/gazebo.material</uri>
          </script>
        </material>
      </visual>
      <visual name='base_footprint_fixed_joint_lump__back_laser_link_visual_1'>
        <pose>-0.354354 -0.2358 0.1914 3.14159 -0 -2.35619</pose>
        <geometry>
          <mesh>
            <scale>1 1 1</scale>
            <uri>model://mobile_robot/meshes/visual/sick_lms-100.stl</uri>
          </mesh>
        </geometry>
        <material>
          <script>
            <name>Gazebo/FlatBlack</name>
            <uri>model://media/materials/scripts/gazebo.material</uri>
          </script>
        </material>
      </visual>
      <visual name='base_footprint_fixed_joint_lump__mirX/front_laser_link_visual_2'>
        <pose>0.429646 0.2358 0.1914 3.14159 -0 0.785398</pose>
        <geometry>
          <mesh>
            <scale>1 1 1</scale>
            <uri>model://mobile_robot/meshes/visual/sick_lms-100.stl</uri>
          </mesh>
        </geometry>
        <material>
          <script>
            <name>Gazebo/FlatBlack</name>
            <uri>model://media/materials/scripts/gazebo.material</uri>
          </script>
        </material>
      </visual>
      <sensor name='back_laser_link' type='ray'>
        <visualize>0</visualize>
        <update_rate>12.5</update_rate>
        <ray>
          <scan>
            <horizontal>
              <samples>541</samples>
              <resolution>1</resolution>
              <min_angle>-2.35619</min_angle>
              <max_angle>2.35619</max_angle>
            </horizontal>
          </scan>
          <range>
            <min>0.05</min>
            <max>29</max>
            <resolution>0.01</resolution>
          </range>
          <noise>
            <type>gaussian</type>
            <mean>0</mean>
            <stddev>0.01</stddev>
          </noise>
        </ray>
        <plugin name='back_laser_link_laserscan' filename='libgazebo_ros_ray_sensor.so'>
          <ros>
            
            <remapping>~/out:=b_scan</remapping>
          </ros>
          <frame_name>back_laser_link</frame_name>
          <output_type>sensor_msgs/LaserScan</output_type>
        </plugin>
        <pose>-0.354354 -0.2358 0.1914 0 0 -2.35619</pose>
      </sensor>
      <sensor name='front_laser_link' type='ray'>
        <visualize>0</visualize>
        <update_rate>12.5</update_rate>
        <ray>
          <scan>
            <horizontal>
              <samples>541</samples>
              <resolution>1</resolution>
              <min_angle>-2.35619</min_angle>
              <max_angle>2.35619</max_angle>
            </horizontal>
          </scan>
          <range>
            <min>0.05</min>
            <max>29</max>
            <resolution>0.01</resolution>
          </range>
          <noise>
            <type>gaussian</type>
            <mean>0</mean>
            <stddev>0.01</stddev>
          </noise>
        </ray>
        <plugin name='front_laser_link_laserscan' filename='libgazebo_ros_ray_sensor.so'>
          <ros>
            
            <remapping>~/out:=f_scan</remapping>
          </ros>
          <frame_name>front_laser_link</frame_name>
          <output_type>sensor_msgs/LaserScan</output_type>
        </plugin>
        <pose>0.429646 0.2358 0.1914 0 -0 0.785398</pose>
      </sensor>
      <sensor name='imu_sensor' type='imu'>
        <plugin name='imu_plugin' filename='libgazebo_ros_imu_sensor.so'>
          <ros>
            
            <remapping>~/out:=imu_data</remapping>
          </ros>
          <initial_orientation_as_reference>0</initial_orientation_as_reference>
          <frame_id>imu_frame</frame_id>
        </plugin>
        <update_rate>50</update_rate>
        <always_on>1</always_on>
        <visualize>1</visualize>
        <imu>
          <angular_velocity>
            <x>
              <noise type='gaussian'>
                <mean>0</mean>
                <stddev>0.0002</stddev>
                <bias_mean>7.5e-06</bias_mean>
                <bias_stddev>8e-07</bias_stddev>
              </noise>
            </x>
            <y>
              <noise type='gaussian'>
                <mean>0</mean>
                <stddev>0.0002</stddev>
                <bias_mean>7.5e-06</bias_mean>
                <bias_stddev>8e-07</bias_stddev>
              </noise>
            </y>
            <z>
              <noise type='gaussian'>
                <mean>0</mean>
                <stddev>0.0002</stddev>
                <bias_mean>7.5e-06</bias_mean>
                <bias_stddev>8e-07</bias_stddev>
              </noise>
            </z>
          </angular_velocity>
          <linear_acceleration>
            <x>
              <noise type='gaussian'>
                <mean>0</mean>
                <stddev>0.017</stddev>
                <bias_mean>0.1</bias_mean>
                <bias_stddev>0.001</bias_stddev>
              </noise>
            </x>
            <y>
              <noise type='gaussian'>
                <mean>0</mean>
                <stddev>0.017</stddev>
                <bias_mean>0.1</bias_mean>
                <bias_stddev>0.001</bias_stddev>
              </noise>
            </y>
            <z>
              <noise type='gaussian'>
                <mean>0</mean>
                <stddev>0.017</stddev>
                <bias_mean>0.1</bias_mean>
                <bias_stddev>0.001</bias_stddev>
              </noise>
            </z>
          </linear_acceleration>
        </imu>
        <pose>0 0 0.25 0 -0 0</pose>
      </sensor>
    </link>
    <joint name='bl_caster_rotation_joint' type='revolute'>
      <pose relative_to='base_footprint'>-0.270154 0.203 0.1565 0 -0 0</pose>
      <parent>base_footprint</parent>
      <child>bl_caster_rotation_link</child>
      <axis>
        <xyz>0 0 1</xyz>
        <limit>
          <lower>-1e+16</lower>
          <upper>1e+16</upper>
        </limit>
        <dynamics>
          <damping>0.01</damping>
          <friction>0</friction>
          <spring_reference>0</spring_reference>
          <spring_stiffness>0</spring_stiffness>
        </dynamics>
      </axis>
    </joint>
    <link name='bl_caster_rotation_link'>
      <pose relative_to='bl_caster_rotation_joint'>0 0 0 0 -0 0</pose>
      <inertial>
        <pose>0 0 -0.0425 0.418879 0 1.5708</pose>
        <mass>0.309754</mass>
        <inertia>
          <ixx>0.000584452</ixx>
          <ixy>0</ixy>
          <ixz>0</ixz>
          <iyy>0.000528726</iyy>
          <iyz>0</iyz>
          <izz>0.000179236</izz>
        </inertia>
      </inertial>
      <collision name='bl_caster_rotation_link_collision'>
        <pose>0 0 0 0 -0 0</pose>
        <geometry>
          <mesh>
            <scale>1 1 1</scale>
            <uri>model://mobile_robot/meshes/collision/caster_wheel_base.stl</uri>
          </mesh>
        </geometry>
        <surface>
          <contact>
            <ode/>
          </contact>
          <friction>
            <ode/>
          </friction>
        </surface>
      </collision>
      <visual name='bl_caster_rotation_link_visual'>
        <pose>0 0 0 0 -0 0</pose>
        <geometry>
          <mesh>
            <scale>1 1 1</scale>
            <uri>model://mobile_robot/meshes/visual/caster_wheel_base.stl</uri>
          </mesh>
        </geometry>
        <material>
          <script>
            <name>Gazebo/Grey</name>
            <uri>model://media/materials/scripts/gazebo.material</uri>
          </script>
        </material>
      </visual>
    </link>
    <joint name='bl_caster_wheel_joint' type='revolute'>
      <pose relative_to='bl_caster_rotation_link'>-0.0382 0 -0.094 0 -0 0</pose>
      <parent>bl_caster_rotation_link</parent>
      <child>bl_caster_wheel_link</child>
      <axis>
        <xyz>0 1 0</xyz>
        <limit>
          <lower>-1e+16</lower>
          <upper>1e+16</upper>
        </limit>
        <dynamics>
          <spring_reference>0</spring_reference>
          <spring_stiffness>0</spring_stiffness>
        </dynamics>
      </axis>
    </joint>
    <link name='bl_caster_wheel_link'>
      <pose relative_to='bl_caster_wheel_joint'>0 0 0 0 -0 0</pose>
      <inertial>
        <pose>0 0 0 1.5708 -0 0</pose>
        <mass>1</mass>
        <inertia>
          <ixx>0.0010619</ixx>
          <ixy>0</ixy>
          <ixz>0</ixz>
          <iyy>0.0010619</iyy>
          <iyz>0</iyz>
          <izz>0.00195312</izz>
        </inertia>
      </inertial>
      <collision name='bl_caster_wheel_link_collision'>
        <pose>0 0 0 1.5708 -0 0</pose>
        <geometry>
          <cylinder>
            <length>0.032</length>
            <radius>0.0625</radius>
          </cylinder>
        </geometry>
        <surface>
          <contact>
            <ode>
              <kp>1e+07</kp>
              <kd>1</kd>
            </ode>
          </contact>
          <friction>
            <ode>
              <mu>1</mu>
              <mu2>1</mu2>
            </ode>
          </friction>
        </surface>
      </collision>
      <visual name='bl_caster_wheel_link_visual'>
        <pose>0 0 0 1.5708 -0 0</pose>
        <geometry>
          <cylinder>
            <length>0.032</length>
            <radius>0.0625</radius>
          </cylinder>
        </geometry>
        <material>
          <script>
            <name>Gazebo/FlatBlack</name>
            <uri>model://media/materials/scripts/gazebo.material</uri>
          </script>
        </material>
      </visual>
      <min_depth>0.01</min_depth>
    </link>
    <joint name='br_caster_rotation_joint' type='revolute'>
      <pose relative_to='base_footprint'>-0.270154 -0.203 0.1565 0 -0 0</pose>
      <parent>base_footprint</parent>
      <child>br_caster_rotation_link</child>
      <axis>
        <xyz>0 0 1</xyz>
        <limit>
          <lower>-1e+16</lower>
          <upper>1e+16</upper>
        </limit>
        <dynamics>
          <damping>0.01</damping>
          <friction>0</friction>
          <spring_reference>0</spring_reference>
          <spring_stiffness>0</spring_stiffness>
        </dynamics>
      </axis>
    </joint>
    <link name='br_caster_rotation_link'>
      <pose relative_to='br_caster_rotation_joint'>0 0 0 0 -0 0</pose>
      <inertial>
        <pose>0 0 -0.0425 0.418879 0 1.5708</pose>
        <mass>0.309754</mass>
        <inertia>
          <ixx>0.000584452</ixx>
          <ixy>0</ixy>
          <ixz>0</ixz>
          <iyy>0.000528726</iyy>
          <iyz>0</iyz>
          <izz>0.000179236</izz>
        </inertia>
      </inertial>
      <collision name='br_caster_rotation_link_collision'>
        <pose>0 0 0 0 -0 0</pose>
        <geometry>
          <mesh>
            <scale>1 1 1</scale>
            <uri>model://mobile_robot/meshes/collision/caster_wheel_base.stl</uri>
          </mesh>
        </geometry>
        <surface>
          <contact>
            <ode/>
          </contact>
          <friction>
            <ode/>
          </friction>
        </surface>
      </collision>
      <visual name='br_caster_rotation_link_visual'>
        <pose>0 0 0 0 -0 0</pose>
        <geometry>
          <mesh>
            <scale>1 1 1</scale>
            <uri>model://mobile_robot/meshes/visual/caster_wheel_base.stl</uri>
          </mesh>
        </geometry>
        <material>
          <script>
            <name>Gazebo/Grey</name>
            <uri>model://media/materials/scripts/gazebo.material</uri>
          </script>
        </material>
      </visual>
    </link>
    <joint name='br_caster_wheel_joint' type='revolute'>
      <pose relative_to='br_caster_rotation_link'>-0.0382 0 -0.094 0 -0 0</pose>
      <parent>br_caster_rotation_link</parent>
      <child>br_caster_wheel_link</child>
      <axis>
        <xyz>0 1 0</xyz>
        <limit>
          <lower>-1e+16</lower>
          <upper>1e+16</upper>
        </limit>
        <dynamics>
          <spring_reference>0</spring_reference>
          <spring_stiffness>0</spring_stiffness>
        </dynamics>
      </axis>
    </joint>
    <link name='br_caster_wheel_link'>
      <pose relative_to='br_caster_wheel_joint'>0 0 0 0 -0 0</pose>
      <inertial>
        <pose>0 0 0 1.5708 -0 0</pose>
        <mass>1</mass>
        <inertia>
          <ixx>0.0010619</ixx>
          <ixy>0</ixy>
          <ixz>0</ixz>
          <iyy>0.0010619</iyy>
          <iyz>0</iyz>
          <izz>0.00195312</izz>
        </inertia>
      </inertial>
      <collision name='br_caster_wheel_link_collision'>
        <pose>0 0 0 1.5708 -0 0</pose>
        <geometry>
          <cylinder>
            <length>0.032</length>
            <radius>0.0625</radius>
          </cylinder>
        </geometry>
        <surface>
          <contact>
            <ode>
              <kp>1e+07</kp>
              <kd>1</kd>
            </ode>
          </contact>
          <friction>
            <ode>
              <mu>1</mu>
              <mu2>1</mu2>
            </ode>
          </friction>
        </surface>
      </collision>
      <visual name='br_caster_wheel_link_visual'>
        <pose>0 0 0 1.5708 -0 0</pose>
        <geometry>
          <cylinder>
            <length>0.032</length>
            <radius>0.0625</radius>
          </cylinder>
        </geometry>
        <material>
          <script>
            <name>Gazebo/FlatBlack</name>
            <uri>model://media/materials/scripts/gazebo.material</uri>
          </script>
        </material>
      </visual>
      <min_depth>0.01</min_depth>
    </link>
    <joint name='fl_caster_rotation_joint' type='revolute'>
      <pose relative_to='base_footprint'>0.341346 0.203 0.1565 0 -0 0</pose>
      <parent>base_footprint</parent>
      <child>fl_caster_rotation_link</child>
      <axis>
        <xyz>0 0 1</xyz>
        <limit>
          <lower>-1e+16</lower>
          <upper>1e+16</upper>
        </limit>
        <dynamics>
          <damping>0.01</damping>
          <friction>0</friction>
          <spring_reference>0</spring_reference>
          <spring_stiffness>0</spring_stiffness>
        </dynamics>
      </axis>
    </joint>
    <link name='fl_caster_rotation_link'>
      <pose relative_to='fl_caster_rotation_joint'>0 0 0 0 -0 0</pose>
      <inertial>
        <pose>0 0 -0.0425 0.418879 0 1.5708</pose>
        <mass>0.309754</mass>
        <inertia>
          <ixx>0.000584452</ixx>
          <ixy>0</ixy>
          <ixz>0</ixz>
          <iyy>0.000528726</iyy>
          <iyz>0</iyz>
          <izz>0.000179236</izz>
        </inertia>
      </inertial>
      <collision name='fl_caster_rotation_link_collision'>
        <pose>0 0 0 0 -0 0</pose>
        <geometry>
          <mesh>
            <scale>1 1 1</scale>
            <uri>model://mobile_robot/meshes/collision/caster_wheel_base.stl</uri>
          </mesh>
        </geometry>
        <surface>
          <contact>
            <ode/>
          </contact>
          <friction>
            <ode/>
          </friction>
        </surface>
      </collision>
      <visual name='fl_caster_rotation_link_visual'>
        <pose>0 0 0 0 -0 0</pose>
        <geometry>
          <mesh>
            <scale>1 1 1</scale>
            <uri>model://mobile_robot/meshes/visual/caster_wheel_base.stl</uri>
          </mesh>
        </geometry>
        <material>
          <script>
            <name>Gazebo/Grey</name>
            <uri>model://media/materials/scripts/gazebo.material</uri>
          </script>
        </material>
      </visual>
    </link>
    <joint name='fl_caster_wheel_joint' type='revolute'>
      <pose relative_to='fl_caster_rotation_link'>-0.0382 0 -0.094 0 -0 0</pose>
      <parent>fl_caster_rotation_link</parent>
      <child>fl_caster_wheel_link</child>
      <axis>
        <xyz>0 1 0</xyz>
        <limit>
          <lower>-1e+16</lower>
          <upper>1e+16</upper>
        </limit>
        <dynamics>
          <spring_reference>0</spring_reference>
          <spring_stiffness>0</spring_stiffness>
        </dynamics>
      </axis>
    </joint>
    <link name='fl_caster_wheel_link'>
      <pose relative_to='fl_caster_wheel_joint'>0 0 0 0 -0 0</pose>
      <inertial>
        <pose>0 0 0 1.5708 -0 0</pose>
        <mass>1</mass>
        <inertia>
          <ixx>0.0010619</ixx>
          <ixy>0</ixy>
          <ixz>0</ixz>
          <iyy>0.0010619</iyy>
          <iyz>0</iyz>
          <izz>0.00195312</izz>
        </inertia>
      </inertial>
      <collision name='fl_caster_wheel_link_collision'>
        <pose>0 0 0 1.5708 -0 0</pose>
        <geometry>
          <cylinder>
            <length>0.032</length>
            <radius>0.0625</radius>
          </cylinder>
        </geometry>
        <surface>
          <contact>
            <ode>
              <kp>1e+07</kp>
              <kd>1</kd>
            </ode>
          </contact>
          <friction>
            <ode>
              <mu>1</mu>
              <mu2>1</mu2>
            </ode>
          </friction>
        </surface>
      </collision>
      <visual name='fl_caster_wheel_link_visual'>
        <pose>0 0 0 1.5708 -0 0</pose>
        <geometry>
          <cylinder>
            <length>0.032</length>
            <radius>0.0625</radius>
          </cylinder>
        </geometry>
        <material>
          <script>
            <name>Gazebo/FlatBlack</name>
            <uri>model://media/materials/scripts/gazebo.material</uri>
          </script>
        </material>
      </visual>
      <min_depth>0.01</min_depth>
    </link>
    <joint name='fr_caster_rotation_joint' type='revolute'>
      <pose relative_to='base_footprint'>0.341346 -0.203 0.1565 0 -0 0</pose>
      <parent>base_footprint</parent>
      <child>fr_caster_rotation_link</child>
      <axis>
        <xyz>0 0 1</xyz>
        <limit>
          <lower>-1e+16</lower>
          <upper>1e+16</upper>
        </limit>
        <dynamics>
          <damping>0.01</damping>
          <friction>0</friction>
          <spring_reference>0</spring_reference>
          <spring_stiffness>0</spring_stiffness>
        </dynamics>
      </axis>
    </joint>
    <link name='fr_caster_rotation_link'>
      <pose relative_to='fr_caster_rotation_joint'>0 0 0 0 -0 0</pose>
      <inertial>
        <pose>0 0 -0.0425 0.418879 0 1.5708</pose>
        <mass>0.309754</mass>
        <inertia>
          <ixx>0.000584452</ixx>
          <ixy>0</ixy>
          <ixz>0</ixz>
          <iyy>0.000528726</iyy>
          <iyz>0</iyz>
          <izz>0.000179236</izz>
        </inertia>
      </inertial>
      <collision name='fr_caster_rotation_link_collision'>
        <pose>0 0 0 0 -0 0</pose>
        <geometry>
          <mesh>
            <scale>1 1 1</scale>
            <uri>model://mobile_robot/meshes/collision/caster_wheel_base.stl</uri>
          </mesh>
        </geometry>
        <surface>
          <contact>
            <ode/>
          </contact>
          <friction>
            <ode/>
          </friction>
        </surface>
      </collision>
      <visual name='fr_caster_rotation_link_visual'>
        <pose>0 0 0 0 -0 0</pose>
        <geometry>
          <mesh>
            <scale>1 1 1</scale>
            <uri>model://mobile_robot/meshes/visual/caster_wheel_base.stl</uri>
          </mesh>
        </geometry>
        <material>
          <script>
            <name>Gazebo/Grey</name>
            <uri>model://media/materials/scripts/gazebo.material</uri>
          </script>
        </material>
      </visual>
    </link>
    <joint name='fr_caster_wheel_joint' type='revolute'>
      <pose relative_to='fr_caster_rotation_link'>-0.0382 0 -0.094 0 -0 0</pose>
      <parent>fr_caster_rotation_link</parent>
      <child>fr_caster_wheel_link</child>
      <axis>
        <xyz>0 1 0</xyz>
        <limit>
          <lower>-1e+16</lower>
          <upper>1e+16</upper>
        </limit>
        <dynamics>
          <spring_reference>0</spring_reference>
          <spring_stiffness>0</spring_stiffness>
        </dynamics>
      </axis>
    </joint>
    <link name='fr_caster_wheel_link'>
      <pose relative_to='fr_caster_wheel_joint'>0 0 0 0 -0 0</pose>
      <inertial>
        <pose>0 0 0 1.5708 -0 0</pose>
        <mass>1</mass>
        <inertia>
          <ixx>0.0010619</ixx>
          <ixy>0</ixy>
          <ixz>0</ixz>
          <iyy>0.0010619</iyy>
          <iyz>0</iyz>
          <izz>0.00195312</izz>
        </inertia>
      </inertial>
      <collision name='fr_caster_wheel_link_collision'>
        <pose>0 0 0 1.5708 -0 0</pose>
        <geometry>
          <cylinder>
            <length>0.032</length>
            <radius>0.0625</radius>
          </cylinder>
        </geometry>
        <surface>
          <contact>
            <ode>
              <kp>1e+07</kp>
              <kd>1</kd>
            </ode>
          </contact>
          <friction>
            <ode>
              <mu>1</mu>
              <mu2>1</mu2>
            </ode>
          </friction>
        </surface>
      </collision>
      <visual name='fr_caster_wheel_link_visual'>
        <pose>0 0 0 1.5708 -0 0</pose>
        <geometry>
          <cylinder>
            <length>0.032</length>
            <radius>0.0625</radius>
          </cylinder>
        </geometry>
        <material>
          <script>
            <name>Gazebo/FlatBlack</name>
            <uri>model://media/materials/scripts/gazebo.material</uri>
          </script>
        </material>
      </visual>
      <min_depth>0.01</min_depth>
    </link>
    <joint name='left_wheel_joint' type='revolute'>
      <pose relative_to='base_footprint'>0 0.222604 0.0625 0 -0 0</pose>
      <parent>base_footprint</parent>
      <child>left_wheel_link</child>
      <axis>
        <xyz>0 1 0</xyz>
        <limit>
          <effort>100</effort>
          <velocity>20</velocity>
          <lower>-1e+16</lower>
          <upper>1e+16</upper>
        </limit>
        <dynamics>
          <spring_reference>0</spring_reference>
          <spring_stiffness>0</spring_stiffness>
        </dynamics>
      </axis>
    </joint>
    <link name='left_wheel_link'>
      <pose relative_to='left_wheel_joint'>0 0 0 0 -0 0</pose>
      <inertial>
        <pose>0 0 0 1.5708 -0 0</pose>
        <mass>1</mass>
        <inertia>
          <ixx>0.0010619</ixx>
          <ixy>0</ixy>
          <ixz>0</ixz>
          <iyy>0.0010619</iyy>
          <iyz>0</iyz>
          <izz>0.00195312</izz>
        </inertia>
      </inertial>
      <collision name='left_wheel_link_collision'>
        <pose>0 0 0 1.5708 -0 0</pose>
        <geometry>
          <cylinder>
            <length>0.032</length>
            <radius>0.0625</radius>
          </cylinder>
        </geometry>
        <surface>
          <contact>
            <ode>
              <kp>1e+07</kp>
              <kd>1</kd>
            </ode>
          </contact>
          <friction>
            <ode>
              <mu>200</mu>
              <mu2>200</mu2>
            </ode>
          </friction>
        </surface>
      </collision>
      <visual name='left_wheel_link_visual'>
        <pose>0 0 0 1.5708 -0 0</pose>
        <geometry>
          <cylinder>
            <length>0.032</length>
            <radius>0.0625</radius>
          </cylinder>
        </geometry>
        <material>
          <script>
            <name>Gazebo/FlatBlack</name>
            <uri>model://media/materials/scripts/gazebo.material</uri>
          </script>
        </material>
      </visual>
      <min_depth>0.01</min_depth>
    </link>
    <joint name='right_wheel_joint' type='revolute'>
      <pose relative_to='base_footprint'>0 -0.222604 0.0625 0 -0 0</pose>
      <parent>base_footprint</parent>
      <child>right_wheel_link</child>
      <axis>
        <xyz>0 1 0</xyz>
        <limit>
          <effort>100</effort>
          <velocity>20</velocity>
          <lower>-1e+16</lower>
          <upper>1e+16</upper>
        </limit>
        <dynamics>
          <spring_reference>0</spring_reference>
          <spring_stiffness>0</spring_stiffness>
        </dynamics>
      </axis>
    </joint>
    <link name='right_wheel_link'>
      <pose relative_to='right_wheel_joint'>0 0 0 0 -0 0</pose>
      <inertial>
        <pose>0 0 0 1.5708 -0 0</pose>
        <mass>1</mass>
        <inertia>
          <ixx>0.0010619</ixx>
          <ixy>0</ixy>
          <ixz>0</ixz>
          <iyy>0.0010619</iyy>
          <iyz>0</iyz>
          <izz>0.00195312</izz>
        </inertia>
      </inertial>
      <collision name='right_wheel_link_collision'>
        <pose>0 0 0 1.5708 -0 0</pose>
        <geometry>
          <cylinder>
            <length>0.032</length>
            <radius>0.0625</radius>
          </cylinder>
        </geometry>
        <surface>
          <contact>
            <ode>
              <kp>1e+07</kp>
              <kd>1</kd>
            </ode>
          </contact>
          <friction>
            <ode>
              <mu>200</mu>
              <mu2>200</mu2>
            </ode>
          </friction>
        </surface>
      </collision>
      <visual name='right_wheel_link_visual'>
        <pose>0 0 0 1.5708 -0 0</pose>
        <geometry>
          <cylinder>
            <length>0.032</length>
            <radius>0.0625</radius>
          </cylinder>
        </geometry>
        <material>
          <script>
            <name>Gazebo/FlatBlack</name>
            <uri>model://media/materials/scripts/gazebo.material</uri>
          </script>
        </material>
      </visual>
      <min_depth>0.01</min_depth>
    </link>
    
    <plugin name='p3d_base_controller' filename='libgazebo_ros_p3d.so'>
      <ros>
        
        <remapping>odom:=odom_p3d</remapping>
      </ros>
      <always_on>1</always_on>
      <update_rate>50.0</update_rate>
      <body_name>base_footprint</body_name>
      <gaussian_noise>0.01</gaussian_noise>
      <frame_name>map</frame_name>
      <topic_name>base_pose_ground_truth</topic_name>
      <xyz_offset>0 0 0</xyz_offset>
      <rpy_offset>0 0 0</rpy_offset>
    </plugin>
    <plugin name='diff_drive_controller' filename='libgazebo_ros_diff_drive.so'>
      <ros>
        
        <remapping>cmd_vel:=cmd_vel</remapping>
        <remapping>odom:=odom</remapping>
      </ros>
      <legacy_mode>0</legacy_mode>
      <always_on>1</always_on>
      <update_rate>1000.0</update_rate>
      <left_joint>left_wheel_joint</left_joint>
      <right_joint>right_wheel_joint</right_joint>
      <wheel_separation>0.445208</wheel_separation>
      <wheel_diameter>0.125</wheel_diameter>
      <wheel_torque>10</wheel_torque>
      <wheel_acceleration>2.8</wheel_acceleration>
      <odometry_frame>odom</odometry_frame>
      <robot_base_frame>base_footprint</robot_base_frame>
      <publish_tf>1</publish_tf>
      <publish_wheel_tf>0</publish_wheel_tf>
      <publish_wheel_joint_state>1</publish_wheel_joint_state>
      <publish_odom>1</publish_odom>
      <publish_odom_tf>1</publish_odom_tf>
      <ros_debug_level>Debug</ros_debug_level>
    </plugin>
    <frame name='base_link_surface_joint' attached_to='base_link'>
      <pose>0.037646 0 0.352 0 -0 0</pose>
    </frame>
    <frame name='surface' attached_to='base_link_surface_joint'/>
    <frame name='base_link_to_back_laser_joint' attached_to='base_link'>
      <pose>-0.354354 -0.2358 0.1914 0 0 -2.35619</pose>
    </frame>
    <frame name='back_laser_link' attached_to='base_link_to_back_laser_joint'/>
    <frame name='base_link_to_front_laser_joint' attached_to='base_link'>
      <pose>0.429646 0.2358 0.1914 0 -0 0.785398</pose>
    </frame>
    <frame name='front_laser_link' attached_to='base_link_to_front_laser_joint'/>
    <frame name='imu_link_to_imu_frame_joint' attached_to='imu_link'>
      <pose>0 0 0 0 -0 0</pose>
    </frame>
    <frame name='imu_frame' attached_to='imu_link_to_imu_frame_joint'/>
    <frame name='base_link_to_imu_joint' attached_to='base_link'>
      <pose>0 0 0.25 0 -0 0</pose>
    </frame>
    <frame name='imu_link' attached_to='base_link_to_imu_joint'/>
    <frame name='us_1_joint' attached_to='base_link'>
      <pose>0.45 -0.12 0.16 0 -0 0</pose>
    </frame>
    <frame name='us_1_frame' attached_to='us_1_joint'/>
    <frame name='us_2_joint' attached_to='base_link'>
      <pose>0.45 0.12 0.16 0 -0 0</pose>
    </frame>
    <frame name='us_2_frame' attached_to='us_2_joint'/>
    <frame name='base_joint' attached_to='base_footprint'>
      <pose>0 0 0 0 -0 0</pose>
    </frame>
    <frame name='base_link' attached_to='base_joint'/>
  </model>
</sdf>
